function throwError(message: string): never {
    throw new Error(message);
}

throwError("Aplicação interrompida. Erro interno!");
console.log("Continue");
console.log("Continue");
console.log("Continue");
console.log("Continue");
